Workbook
Name ListaModelos: Planilha2!$D$4:$D$8
Name ListaStatus: Planilha2!$F$2:$F$6

Sheet DASHBOARD
A1: PRODUÇÃO | PCP
A3: =NOW() -> 46252.348 | G3: Modelo | H3: BYD6121BC4BEVF1S_CHASSIS BC12S03 | J3: Status | K3: Todos
A5: ORDENS PLANEJADA | C5: PRODUÇÃO REALIZADA | E5: ADERÊNCIA AO PLANO | G5: BACKLOG | I5: FILL RATE | K5: CUMPRIMENTO DE PRAZO
A7: =IF(H3="Todos",COUNTA(BASE_OP!C:C)-1,COUNTIF(BASE_OP!C:C,H3)) -> 1 | C7: =CALCULOS!B3 -> 1 | E7: {=IFERROR(SUMPRODUCT(BASE_OP!$F$2:$F$9916,--(BASE_OP!$A$2:$A$9916<>""),--((DASHBOARD!$H$3="Todos")+(BASE_OP!$C$2:$C$9916=DASHBOARD!$H$3)>0),--((DASHBOARD!$K$3="Todos")+(BASE_OP!$I$2:$I$9916=DASHBOARD!$K$3)>0))/SUMPRODUCT(BASE_OP!$D$2:$D$9916,--(BASE_OP!$A$2:$A$9916<>""),--((DASHBOARD!$H$3="Todos")+(BASE_OP!$C$2:$C$9916=DASHBOARD!$H$3)>0),--((DASHBOARD!$K$3="Todos")+(BASE_OP!$I$2:$I$9916=DASHBOARD!$K$3)>0)),0)} -> 1 | G7: =CALCULOS!B5 -> 0 | I7: =CALCULOS!B10 -> 1 | K7: =CALCULOS!B9 -> 1
A9: ORDENS DE PRODUÇÃO (OPs)
A10: OPs LIBERADAS | D10: OPs EM PRODUÇÃO | G10: AGUARDANDO MATERIAL | J10: OPs ATRASADAS
A11: =CALCULOS!B11 -> 1 | D11: =CALCULOS!B12 -> 5 | G11: =CALCULOS!B13 -> 1 | J11: =CALCULOS!B8 -> 1

Sheet Planilha3
A1: =CONT.SE(BASE_OP[Modelo Chassi];H3)

Sheet Planilha2
F1: Lista_Status
F2: Todos
A3: Modelo | B3: Contagem de Modelo | D3: Lista_Modelos | F3: Ordem apontada em aberto
A4: BC22S02-6800100_BANCO MOT CHASSI | B4: =IF(DASHBOARD!$H$3="Todos",COUNTIF(BASE_OP!$C:$C,A4),IF(DASHBOARD!$H$3=A4,COUNTIF(BASE_OP!$C:$C,A4),0)) -> 0 | D4: Todos | F4: Aguardando apontamento em aberta
A5: BYD6121BC4BEVF1S_CHASSIS BC12S03 | B5: =IF(DASHBOARD!$H$3="Todos",COUNTIF(BASE_OP!$C:$C,A5),IF(DASHBOARD!$H$3=A5,COUNTIF(BASE_OP!$C:$C,A5),0)) -> 1 | D5: CHASSIS ELECTRIC BUS BC22S02 | F5: Em Produção
A6: CHASSIS ELECTRIC BUS BC22S02 | B6: =IF(DASHBOARD!$H$3="Todos",COUNTIF(BASE_OP!$C:$C,A6),IF(DASHBOARD!$H$3=A6,COUNTIF(BASE_OP!$C:$C,A6),0)) -> 0 | D6: CHASSIS ONIBUS ELETRICO BC10S01 | F6: Parada
A7: CHASSIS ONIBUS ELETRICO BC10S01 | B7: =IF(DASHBOARD!$H$3="Todos",COUNTIF(BASE_OP!$C:$C,A7),IF(DASHBOARD!$H$3=A7,COUNTIF(BASE_OP!$C:$C,A7),0)) -> 0 | D7: BC22S02-6800100_BANCO MOT CHASSI
D8: BYD6121BC4BEVF1S_CHASSIS BC12S03

Sheet BASE_OP
A1: OP | B1: Material | C1: Modelo | D1: Qtd. Planejada | E1: Qtd. Fornecida | F1: Qtd. Produzida | G1: Data Planejada | H1: Data de conclusão base | I1: Status | J1: Data de entrada | K1: Motivo do Atraso | L1: Dias de Atraso | M1: Aderência | N1: Fechada/ Aberta
A2: 19000001790 | B2: 19903843-00 | C2: CHASSIS ONIBUS ELETRICO BC10S01 | D2: 1 | E2: 1 | F2: 1 | G2: 46234 | H2: 46234 | I2: Ordem apontada em aberto | J2: 46196 | K2: - | M2: =IF(D2=0,0,F2/D2) -> 1 | N2: =IF(I2<>"Encerrada","Em aberto",IF(H2<=G2,"Sim","Não")) -> Em aberto
A3: 19000001791 | B3: 19903843-00 | C3: CHASSIS ONIBUS ELETRICO BC10S01 | D3: 1 | E3: 1 | F3: 1 | G3: 46234 | H3: 46234 | I3: Ordem apontada em aberto | J3: 46196 | K3: Problemas de qualidade | M3: =IF(D3=0,0,F3/D3) -> 1 | N3: =IF(I3<>"Encerrada","Em aberto",IF(H3<=G3,"Sim","Não")) -> Em aberto
A4: 19000001792 | B4: 19903843-00 | C4: CHASSIS ONIBUS ELETRICO BC10S01 | D4: 1 | E4: 1 | F4: 1 | G4: 46234 | H4: 46234 | I4: Ordem apontada em aberto | J4: 46196 | K4: Ordem pendente de apontamento | M4: =IF(D4=0,0,F4/D4) -> 1 | N4: =IF(I4<>"Encerrada","Em aberto",IF(H4<=G4,"Sim","Não")) -> Em aberto
A5: 19000001793 | B5: 19903843-00 | C5: CHASSIS ONIBUS ELETRICO BC10S01 | D5: 1 | E5: 1 | F5: 1 | G5: 46234 | H5: 46234 | I5: Ordem apontada em aberto | J5: 46196 | K5: - | M5: =IF(D5=0,0,F5/D5) -> 1 | N5: =IF(I5<>"Encerrada","Em aberto",IF(H5<=G5,"Sim","Não")) -> Em aberto
A6: 19000001794 | B6: 19903843-00 | C6: CHASSIS ONIBUS ELETRICO BC10S01 | D6: 1 | E6: 1 | F6: 1 | G6: 46234 | H6: 46234 | I6: Ordem apontada em aberto | J6: 46196 | K6: - | M6: =IF(D6=0,0,F6/D6) -> 1 | N6: =IF(I6<>"Encerrada","Em aberto",IF(H6<=G6,"Sim","Não")) -> Em aberto
A7: 19000001795 | B7: 19903843-00 | C7: CHASSIS ONIBUS ELETRICO BC10S01 | D7: 1 | E7: 1 | F7: 1 | G7: 46234 | H7: 46234 | I7: Ordem apontada em aberto | J7: 46196 | K7: - | M7: =IF(D7=0,0,F7/D7) -> 1 | N7: =IF(I7<>"Encerrada","Em aberto",IF(H7<=G7,"Sim","Não")) -> Em aberto
A8: 19000001832 | B8: 19903843-00 | C8: CHASSIS ONIBUS ELETRICO BC10S01 | D8: 1 | E8: 1 | F8: 1 | G8: 46234 | H8: 46234 | I8: Ordem apontada em aberto | J8: 46219 | K8: - | M8: =IF(D8=0,0,F8/D8) -> 1 | N8: =IF(I8<>"Encerrada","Em aberto",IF(H8<=G8,"Sim","Não")) -> Em aberto
A9: 19000001842 | B9: 19903843-00 | C9: CHASSIS ONIBUS ELETRICO BC10S01 | D9: 1 | E9: 1 | F9: 1 | G9: 46234 | H9: 46234 | I9: Ordem apontada em aberto | J9: 46219 | K9: - | M9: =IF(D9=0,0,F9/D9) -> 1 | N9: =IF(I9<>"Encerrada","Em aberto",IF(H9<=G9,"Sim","Não")) -> Em aberto
A10: 19000002032 | B10: 19144528-00 | C10: BC22S02-6800100_BANCO MOT CHASSI | D10: 220 | E10: 220 | F10: 220 | G10: 46237 | H10: 46237 | I10: Ordem apontada em aberto | J10: 46237 | K10: - | M10: =IF(D10=0,0,F10/D10) -> 1 | N10: =IF(I10<>"Encerrada","Em aberto",IF(H10<=G10,"Sim","Não")) -> Em aberto
A11: 19000001838 | B11: 19903843-00 | C11: CHASSIS ONIBUS ELETRICO BC10S01 | D11: 1 | E11: 1 | F11: 1 | G11: 46237 | H11: 46237 | I11: Ordem apontada em aberto | J11: 46219 | K11: - | M11: =IF(D11=0,0,F11/D11) -> 1 | N11: =IF(I11<>"Encerrada","Em aberto",IF(H11<=G11,"Sim","Não")) -> Em aberto
A12: 19000001886 | B12: 19903843-00 | C12: CHASSIS ONIBUS ELETRICO BC10S01 | D12: 1 | E12: 1 | F12: 1 | G12: 46237 | H12: 46237 | I12: Ordem apontada em aberto | J12: 46226 | K12: - | M12: =IF(D12=0,0,F12/D12) -> 1 | N12: =IF(I12<>"Encerrada","Em aberto",IF(H12<=G12,"Sim","Não")) -> Em aberto
A13: 19000001887 | B13: 19903843-00 | C13: CHASSIS ONIBUS ELETRICO BC10S01 | D13: 1 | E13: 1 | F13: 1 | G13: 46237 | H13: 46237 | I13: Ordem apontada em aberto | J13: 46226 | K13: - | M13: =IF(D13=0,0,F13/D13) -> 1 | N13: =IF(I13<>"Encerrada","Em aberto",IF(H13<=G13,"Sim","Não")) -> Em aberto
... A22: 19000001896 | B22: 19903843-00 | C22: CHASSIS ONIBUS ELETRICO BC10S01 | D22: 1 | E22: 1 | F22: 1 | G22: 46238 | H22: 46238 | I22: Ordem apontada em aberto | J22: 46226 | K22: - | M22: =IF(D22=0,0,F22/D22) -> 1 | N22: =IF(I22<>"Encerrada","Em aberto",IF(H22<=G22,"Sim","Não")) -> Em aberto
A23: 19000001897 | B23: 19903843-00 | C23: CHASSIS ONIBUS ELETRICO BC10S01 | D23: 1 | E23: 1 | F23: 1 | G23: 46238 | H23: 46238 | I23: Ordem apontada em aberto | J23: 46226 | K23: - | L23: 1 | M23: =IF(D23=0,0,F23/D23) -> 1 | N23: =IF(I23<>"Encerrada","Em aberto",IF(H23<=G23,"Sim","Não")) -> Em aberto
A24: 19000001898 | B24: 19903843-00 | C24: CHASSIS ONIBUS ELETRICO BC10S01 | D24: 1 | E24: 1 | F24: 1 | G24: 46239 | H24: 46239 | I24: Ordem apontada em aberto | J24: 46226 | K24: - | M24: =IF(D24=0,0,F24/D24) -> 1 | N24: =IF(I24<>"Encerrada","Em aberto",IF(H24<=G24,"Sim","Não")) -> Em aberto
A25: 19000001899 | B25: 19903843-00 | C25: CHASSIS ONIBUS ELETRICO BC10S01 | D25: 1 | E25: 1 | F25: 1 | G25: 46239 | H25: 46239 | I25: Ordem apontada em aberto | J25: 46226 | K25: - | M25: =IF(D25=0,0,F25/D25) -> 1 | N25: =IF(I25<>"Encerrada","Em aberto",IF(H25<=G25,"Sim","Não")) -> Em aberto
A26: 19000001900 | B26: 19903843-00 | C26: CHASSIS ONIBUS ELETRICO BC10S01 | D26: 1 | E26: 1 | F26: 1 | G26: 46239 | H26: 46239 | I26: Ordem apontada em aberto | J26: 46226 | K26: - | M26: =IF(D26=0,0,F26/D26) -> 1 | N26: =IF(I26<>"Encerrada","Em aberto",IF(H26<=G26,"Sim","Não")) -> Em aberto
A27: 19000001901 | B27: 19903843-00 | C27: CHASSIS ONIBUS ELETRICO BC10S01 | D27: 1 | E27: 1 | F27: 1 | G27: 46239 | H27: 46239 | I27: Ordem apontada em aberto | J27: 46226 | K27: - | M27: =IF(D27=0,0,F27/D27) -> 1 | N27: =IF(I27<>"Encerrada","Em aberto",IF(H27<=G27,"Sim","Não")) -> Em aberto
A28: 19000001902 | B28: 19903843-00 | C28: CHASSIS ONIBUS ELETRICO BC10S01 | D28: 1 | E28: 1 | F28: 1 | G28: 46239 | H28: 46239 | I28: Ordem apontada em aberto | J28: 46226 | K28: - | M28: =IF(D28=0,0,F28/D28) -> 1 | N28: =IF(I28<>"Encerrada","Em aberto",IF(H28<=G28,"Sim","Não")) -> Em aberto
A29: 19000001903 | B29: 19903843-00 | C29: CHASSIS ONIBUS ELETRICO BC10S01 | D29: 1 | E29: 1 | F29: 1 | G29: 46239 | H29: 46239 | I29: Ordem apontada em aberto | J29: 46226 | K29: - | M29: =IF(D29=0,0,F29/D29) -> 1 | N29: =IF(I29<>"Encerrada","Em aberto",IF(H29<=G29,"Sim","Não")) -> Em aberto
A30: 19000001969 | B30: 20983890-00 | C30: BYD6121BC4BEVF1S_CHASSIS BC12S03 | D30: 1 | E30: 1 | F30: 1 | G30: 46239 | H30: 46239 | I30: Ordem apontada em aberto | J30: 46233 | K30: - | M30: =IF(D30=0,0,F30/D30) -> 1 | N30: =IF(I30<>"Encerrada","Em aberto",IF(H30<=G30,"Sim","Não")) -> Em aberto
A31: 19000001904 | B31: 19903843-00 | C31: CHASSIS ONIBUS ELETRICO BC10S01 | D31: 1 | E31: 1 | F31: 1 | G31: 46240 | H31: 46240 | I31: Ordem apontada em aberto | J31: 46226 | K31: - | M31: =IF(D31=0,0,F31/D31) -> 1 | N31: =IF(I31<>"Encerrada","Em aberto",IF(H31<=G31,"Sim","Não")) -> Em aberto
A32: 19000001905 | B32: 19903843-00 | C32: CHASSIS ONIBUS ELETRICO BC10S01 | D32: 1 | E32: 1 | F32: 1 | G32: 46240 | H32: 46240 | I32: Ordem apontada em aberto | J32: 46226 | K32: - | M32: =IF(D32=0,0,F32/D32) -> 1 | N32: =IF(I32<>"Encerrada","Em aberto",IF(H32<=G32,"Sim","Não")) -> Em aberto
A33: 19000001906 | B33: 19903843-00 | C33: CHASSIS ONIBUS ELETRICO BC10S01 | D33: 1 | E33: 1 | F33: 1 | G33: 46240 | H33: 46240 | I33: Ordem apontada em aberto | J33: 46226 | K33: - | M33: =IF(D33=0,0,F33/D33) -> 1 | N33: =IF(I33<>"Encerrada","Em aberto",IF(H33<=G33,"Sim","Não")) -> Em aberto
A34: 19000001907 | B34: 19903843-00 | C34: CHASSIS ONIBUS ELETRICO BC10S01 | D34: 1 | E34: 1 | F34: 1 | G34: 46240 | H34: 46240 | I34: Ordem apontada em aberto | J34: 46226 | K34: - | M34: =IF(D34=0,0,F34/D34) -> 1 | N34: =IF(I34<>"Encerrada","Em aberto",IF(H34<=G34,"Sim","Não")) -> Em aberto
A35: 19000001908 | B35: 19903843-00 | C35: CHASSIS ONIBUS ELETRICO BC10S01 | D35: 1 | E35: 1 | F35: 1 | G35: 46240 | H35: 46240 | I35: Ordem apontada em aberto | J35: 46226 | K35: - | M35: =IF(D35=0,0,F35/D35) -> 1 | N35: =IF(I35<>"Encerrada","Em aberto",IF(H35<=G35,"Sim","Não")) -> Em aberto
... A73: 19000001841 | B73: 19903843-00 | C73: CHASSIS ONIBUS ELETRICO BC10S01 | D73: 1 | E73: 0 | F73: 0 | G73: 46252 | H73: 46252 | I73: Parada | J73: 46219 | K73: - | M73: =IF(D73=0,0,F73/D73) -> 0 | N73: =IF(I73<>"Encerrada","Em aberto",IF(H73<=G73,"Sim","Não")) -> Em aberto
A74: 19000001688 | B74: 19006834-00 | C74: CHASSIS ELECTRIC BUS BC22S02 | D74: 1 | E74: 1 | F74: 1 | G74: 46205 | H74: 46206 | I74: Parada | J74: 46182 | K74: - | M74: =IF(D74=0,0,F74/D74) -> 1 | N74: =IF(I74<>"Encerrada","Em aberto",IF(H74<=G74,"Sim","Não")) -> Em aberto
A75: 19000001689 | B75: 19006834-00 | C75: CHASSIS ELECTRIC BUS BC22S02 | D75: 1 | E75: 1 | F75: 1 | G75: 46205 | H75: 46206 | I75: Parada | J75: 46183 | K75: - | M75: =IF(D75=0,0,F75/D75) -> 1 | N75: =IF(I75<>"Encerrada","Em aberto",IF(H75<=G75,"Sim","Não")) -> Em aberto
A76: 19000001690 | B76: 19006834-00 | C76: CHASSIS ELECTRIC BUS BC22S02 | D76: 1 | E76: 1 | F76: 1 | G76: 46205 | H76: 46206 | I76: Parada | J76: 46183 | K76: - | M76: =IF(D76=0,0,F76/D76) -> 1 | N76: =IF(I76<>"Encerrada","Em aberto",IF(H76<=G76,"Sim","Não")) -> Em aberto
A77: 19000002075 | B77: 19006834-00 | C77: CHASSIS ELECTRIC BUS BC22S02 | D77: 1 | E77: 0 | F77: 0 | G77: 46254 | H77: 46254 | I77: Parada | J77: 46239 | K77: - | M77: =IF(D77=0,0,F77/D77) -> 0 | N77: =IF(I77<>"Encerrada","Em aberto",IF(H77<=G77,"Sim","Não")) -> Em aberto
A78: 19000002076 | B78: 19006834-00 | C78: CHASSIS ELECTRIC BUS BC22S02 | D78: 1 | E78: 0 | F78: 0 | G78: 46255 | H78: 46255 | I78: Parada | J78: 46239 | K78: - | M78: =IF(D78=0,0,F78/D78) -> 0 | N78: =IF(I78<>"Encerrada","Em aberto",IF(H78<=G78,"Sim","Não")) -> Em aberto
A79: 19000002077 | B79: 19006834-00 | C79: CHASSIS ELECTRIC BUS BC22S02 | D79: 1 | E79: 0 | F79: 0 | G79: 46255 | H79: 46255 | I79: Parada | J79: 46239 | K79: - | M79: =IF(D79=0,0,F79/D79) -> 0 | N79: =IF(I79<>"Encerrada","Em aberto",IF(H79<=G79,"Sim","Não")) -> Em aberto
A80: 19000002078 | B80: 19006834-00 | C80: CHASSIS ELECTRIC BUS BC22S02 | D80: 1 | E80: 0 | F80: 0 | G80: 46255 | H80: 46255 | I80: Parada | J80: 46239 | K80: - | M80: =IF(D80=0,0,F80/D80) -> 0 | N80: =IF(I80<>"Encerrada","Em aberto",IF(H80<=G80,"Sim","Não")) -> Em aberto
A81: 19000002118 | B81: 19006834-00 | C81: CHASSIS ELECTRIC BUS BC22S02 | D81: 1 | E81: 0 | F81: 0 | G81: 46255 | H81: 46255 | I81: Parada | J81: 46244 | K81: - | M81: =IF(D81=0,0,F81/D81) -> 0 | N81: =IF(I81<>"Encerrada","Em aberto",IF(H81<=G81,"Sim","Não")) -> Em aberto
A82: 19000002119 | B82: 19006834-00 | C82: CHASSIS ELECTRIC BUS BC22S02 | D82: 1 | E82: 0 | F82: 0 | G82: 46258 | H82: 46258 | I82: Parada | J82: 46244 | K82: - | M82: =IF(D82=0,0,F82/D82) -> 0 | N82: =IF(I82<>"Encerrada","Em aberto",IF(H82<=G82,"Sim","Não")) -> Em aberto
A83: 19000002120 | B83: 19006834-00 | C83: CHASSIS ELECTRIC BUS BC22S02 | D83: 1 | E83: 0 | F83: 0 | G83: 46258 | H83: 46258 | I83: Parada | J83: 46244 | K83: - | M83: =IF(D83=0,0,F83/D83) -> 0 | N83: =IF(I83<>"Encerrada","Em aberto",IF(H83<=G83,"Sim","Não")) -> Em aberto
A84: 19000002121 | B84: 19006834-00 | C84: CHASSIS ELECTRIC BUS BC22S02 | D84: 1 | E84: 0 | F84: 0 | G84: 46258 | H84: 46258 | I84: Parada | J84: 46244 | K84: - | M84: =IF(D84=0,0,F84/D84) -> 0 | N84: =IF(I84<>"Encerrada","Em aberto",IF(H84<=G84,"Sim","Não")) -> Em aberto
A85: 19000002122 | B85: 19006834-00 | C85: CHASSIS ELECTRIC BUS BC22S02 | D85: 1 | E85: 0 | F85: 0 | G85: 46259 | H85: 46259 | I85: Parada | J85: 46244 | K85: - | M85: =IF(D85=0,0,F85/D85) -> 0 | N85: =IF(I85<>"Encerrada","Em aberto",IF(H85<=G85,"Sim","Não")) -> Em aberto
...

Sheet CALCULOS
A1: INDICADOR | B1: VALOR | D1: Data | E1: Planejado ordens | F1: Realizado | G1: Backlog | I1: Status | J1: Qtd | L1: Motivo | M1: Qtd
A2: Produção Planejada | B2: {=COUNTA(_xlfn.UNIQUE(_xlfn._xlws.FILTER(BASE_OP!$A$2:$A$9916,BASE_OP!$A$2:$A$9916<>"")))} -> 101 | D2: 46205 | E2: {=IFERROR(INDEX(_xlfn._xlws.FILTER(BASE_OP!$D$2:$D$9916,BASE_OP!$G$2:$G$9916=D2),COUNTIF($D$2:D2,D2)),"")} -> 1 | F2: {=IFERROR(INDEX(_xlfn._xlws.FILTER(BASE_OP!$F$2:$F$9916,BASE_OP!$G$2:$G$9916=D2),COUNTIF($D$2:D2,D2)),0)} -> 1 | G2: =IF(E2="","",MAX(0,E2-F2)) -> 0 | I2: Liberada | J2: =COUNTIF(BASE_OP!$I:$I,I2) -> 0 | L2: Falta de material | M2: =COUNTIF(BASE_OP!$K:$K,L2) -> 0
A3: Produção Realizada | B3: {=IFERROR(SUMPRODUCT(BASE_OP!$F$2:$F$9916,--(BASE_OP!$A$2:$A$9916<>""),--((DASHBOARD!$H$3="Todos")+(BASE_OP!$C$2:$C$9916=DASHBOARD!$H$3)>0),--((DASHBOARD!$K$3="Todos")+(BASE_OP!$I$2:$I$9916=DASHBOARD!$K$3)>0)),0)} -> 1 | D3: 46205 | E3: {=IFERROR(INDEX(_xlfn._xlws.FILTER(BASE_OP!$D$2:$D$9916,BASE_OP!$G$2:$G$9916=D3),COUNTIF($D$2:D3,D3)),"")} -> 1 | F3: {=IFERROR(INDEX(_xlfn._xlws.FILTER(BASE_OP!$F$2:$F$9916,BASE_OP!$G$2:$G$9916=D3),COUNTIF($D$2:D3,D3)),0)} -> 1 | G3: =IF(E3="","",MAX(0,E3-F3)) -> 0 | I3: Em Produção | J3: =COUNTIF(BASE_OP!$I:$I,I3) -> 5 | L3: Máquina parada | M3: =COUNTIF(BASE_OP!$K:$K,L3) -> 0
A4: Aderência ao Plano | B4: {=IFERROR(MIN(Realizado/Planejado,1),0)} -> 0 | D4: 46205 | E4: {=IFERROR(INDEX(_xlfn._xlws.FILTER(BASE_OP!$D$2:$D$9916,BASE_OP!$G$2:$G$9916=D4),COUNTIF($D$2:D4,D4)),"")} -> 1 | F4: {=IFERROR(INDEX(_xlfn._xlws.FILTER(BASE_OP!$F$2:$F$9916,BASE_OP!$G$2:$G$9916=D4),COUNTIF($D$2:D4,D4)),0)} -> 1 | G4: =IF(E4="","",MAX(0,E4-F4)) -> 0 | I4: Aguardando Material | J4: =COUNTIF(BASE_OP!$I:$I,I4) -> 0 | L4: Manutenção | M4: =COUNTIF(BASE_OP!$K:$K,L4) -> 0
A5: Backlog | B5: =IF(DASHBOARD!H3="Todos",SUM(BASE_OP!D2:D9916)-SUM(BASE_OP!F2:F9916),SUMIF(BASE_OP!C2:C9916,DASHBOARD!H3,BASE_OP!D2:D9916)-SUMIF(BASE_OP!C2:C9916,DASHBOARD!H3,BASE_OP!F2:F9916)) -> 0 | D5: 46234 | E5: {=IFERROR(INDEX(_xlfn._xlws.FILTER(BASE_OP!$D$2:$D$9916,BASE_OP!$G$2:$G$9916=D5),COUNTIF($D$2:D5,D5)),"")} -> 1 | F5: {=IFERROR(INDEX(_xlfn._xlws.FILTER(BASE_OP!$F$2:$F$9916,BASE_OP!$G$2:$G$9916=D5),COUNTIF($D$2:D5,D5)),0)} -> 1 | G5: =IF(E5="","",MAX(0,E5-F5)) -> 0 | I5: Aguardando Qualidade | J5: =COUNTIF(BASE_OP!$I:$I,I5) -> 0 | L5: Problemas de qualidade | M5: =COUNTIF(BASE_OP!$K:$K,L5) -> 1
A6: OPs em Aberto | B6: {=COUNTA(_xlfn.UNIQUE(_xlfn._xlws.FILTER(BASE_OP!$A$2:$A$9916,(BASE_OP!$I$2:$I$9916<>"Encerrada")*(BASE_OP!$A$2:$A$9916<>""))))} -> 101 | D6: 46234 | E6: {=IFERROR(INDEX(_xlfn._xlws.FILTER(BASE_OP!$D$2:$D$9916,BASE_OP!$G$2:$G$9916=D6),COUNTIF($D$2:D6,D6)),"")} -> 1 | F6: {=IFERROR(INDEX(_xlfn._xlws.FILTER(BASE_OP!$F$2:$F$9916,BASE_OP!$G$2:$G$9916=D6),COUNTIF($D$2:D6,D6)),0)} -> 1 | G6: =IF(E6="","",MAX(0,E6-F6)) -> 0 | I6: Parada | J6: =COUNTIF(BASE_OP!$I:$I,I6) -> 31 | L6: Falta de operador | M6: =COUNTIF(BASE_OP!$K:$K,L6) -> 0
A7: OPs Encerradas | B7: {=COUNTA(_xlfn.UNIQUE(_xlfn._xlws.FILTER(BASE_OP!$A$2:$A$9916,(BASE_OP!$I$2:$I$9916="Encerrada")*(BASE_OP!$A$2:$A$9916<>""))))} -> 1 | D7: 46234 | E7: {=IFERROR(INDEX(_xlfn._xlws.FILTER(BASE_OP!$D$2:$D$9916,BASE_OP!$G$2:$G$9916=D7),COUNTIF($D$2:D7,D7)),"")} -> 1 | F7: {=IFERROR(INDEX(_xlfn._xlws.FILTER(BASE_OP!$F$2:$F$9916,BASE_OP!$G$2:$G$9916=D7),COUNTIF($D$2:D7,D7)),0)} -> 1 | G7: =IF(E7="","",MAX(0,E7-F7)) -> 0 | I7: Encerrada | J7: =COUNTIF(BASE_OP!$I:$I,I7) -> 0 | L7: Ajustes de processo | M7: =COUNTIF(BASE_OP!$K:$K,L7) -> 0
A8: OPs Atrasadas | B8: =COUNTIF(BASE_OP!L:L,">0") -> 1 | D8: 46234 | E8: {=IFERROR(INDEX(_xlfn._xlws.FILTER(BASE_OP!$D$2:$D$9916,BASE_OP!$G$2:$G$9916=D8),COUNTIF($D$2:D8,D8)),"")} -> 1 | F8: {=IFERROR(INDEX(_xlfn._xlws.FILTER(BASE_OP!$F$2:$F$9916,BASE_OP!$G$2:$G$9916=D8),COUNTIF($D$2:D8,D8)),0)} -> 1 | G8: =IF(E8="","",MAX(0,E8-F8)) -> 0 | I8: Ordem apontada em aberto | J8: =COUNTIF(BASE_OP!$I:$I,I8) -> 54 | L8: Falta Apontamento | M8: =COUNTIF(BASE_OP!$K:$K,L8) -> 0
A9: Cumprimento de Prazo | B9: {=IFERROR(COUNTA(_xlfn.UNIQUE(_xlfn._xlws.FILTER(BASE_OP!$A$2:$A$9916,(BASE_OP!$H$2:$H$9916<>"")*(BASE_OP!$H$2:$H$9916<=BASE_OP!$G$2:$G$9916)*(BASE_OP!$A$2:$A$9916<>"")*IF(DASHBOARD!$H$3="Todos",1,BASE_OP!$C$2:$C$9916=DASHBOARD!$H$3))))/COUNTA(_xlfn.UNIQUE(_xlfn._xlws.FILTER(BASE_OP!$A$2:$A$9916,(BASE_OP!$A$2:$A$9916<>"")*IF(DASHBOARD!$H$3="Todos",1,BASE_OP!$C$2:$C$9916=DASHBOARD!$H$3)))),0)} -> 1 | D9: 46234 | E9: {=IFERROR(INDEX(_xlfn._xlws.FILTER(BASE_OP!$D$2:$D$9916,BASE_OP!$G$2:$G$9916=D9),COUNTIF($D$2:D9,D9)),"")} -> 1 | F9: {=IFERROR(INDEX(_xlfn._xlws.FILTER(BASE_OP!$F$2:$F$9916,BASE_OP!$G$2:$G$9916=D9),COUNTIF($D$2:D9,D9)),0)} -> 1 | G9: =IF(E9="","",MAX(0,E9-F9)) -> 0 | I9: Aguardando apontamento em aberta | J9: =COUNTIF(BASE_OP!$I:$I,I9) -> 11 | L9: Ordem pendente de apontamento | M9: =COUNTIF(BASE_OP!$K:$K,L9) -> 1
A10: Fill Rate | B10: {=IFERROR(COUNTA(_xlfn.UNIQUE(_xlfn._xlws.FILTER(BASE_OP!$A$2:$A$9916,(BASE_OP!$F$2:$F$9916>0)*IF(DASHBOARD!$H$3="Todos",1,BASE_OP!$C$2:$C$9916=DASHBOARD!$H$3))))/COUNTA(_xlfn.UNIQUE(_xlfn._xlws.FILTER(BASE_OP!$A$2:$A$9916,(BASE_OP!$A$2:$A$9916<>"")*IF(DASHBOARD!$H$3="Todos",1,BASE_OP!$C$2:$C$9916=DASHBOARD!$H$3)))),0)} -> 1 | D10: 46234 | E10: {=IFERROR(INDEX(_xlfn._xlws.FILTER(BASE_OP!$D$2:$D$9916,BASE_OP!$G$2:$G$9916=D10),COUNTIF($D$2:D10,D10)),"")} -> 1 | F10: {=IFERROR(INDEX(_xlfn._xlws.FILTER(BASE_OP!$F$2:$F$9916,BASE_OP!$G$2:$G$9916=D10),COUNTIF($D$2:D10,D10)),0)} -> 1 | G10: =IF(E10="","",MAX(0,E10-F10)) -> 0 | I10: Em Produção | J10: =COUNTIF(BASE_OP!$I:$I,I10) -> 5
A11: OPs Liberadas | B11: {=IFERROR(COUNTA(_xlfn.UNIQUE(_xlfn._xlws.FILTER(BASE_OP!$A$2:$A$9916,(BASE_OP!$I$2:$I$9916="Liberada")*(BASE_OP!$A$2:$A$9916<>"")))),0)} -> 1 | D11: 46234 | E11: {=IFERROR(INDEX(_xlfn._xlws.FILTER(BASE_OP!$D$2:$D$9916,BASE_OP!$G$2:$G$9916=D11),COUNTIF($D$2:D11,D11)),"")} -> 1 | F11: {=IFERROR(INDEX(_xlfn._xlws.FILTER(BASE_OP!$F$2:$F$9916,BASE_OP!$G$2:$G$9916=D11),COUNTIF($D$2:D11,D11)),0)} -> 1 | G11: =IF(E11="","",MAX(0,E11-F11)) -> 0
A12: OPs Em Produção | B12: {=IFERROR(COUNTA(_xlfn.UNIQUE(_xlfn._xlws.FILTER(BASE_OP!$A$2:$A$9916,(BASE_OP!$I$2:$I$9916="Em Produção")*(BASE_OP!$A$2:$A$9916<>"")))),0)} -> 5 | D12: 46234 | E12: {=IFERROR(INDEX(_xlfn._xlws.FILTER(BASE_OP!$D$2:$D$9916,BASE_OP!$G$2:$G$9916=D12),COUNTIF($D$2:D12,D12)),"")} -> 1 | F12: {=IFERROR(INDEX(_xlfn._xlws.FILTER(BASE_OP!$F$2:$F$9916,BASE_OP!$G$2:$G$9916=D12),COUNTIF($D$2:D12,D12)),0)} -> 1 | G12: =IF(E12="","",MAX(0,E12-F12)) -> 0
A13: OPs Aguardando Material | B13: {=IFERROR(COUNTA(_xlfn.UNIQUE(_xlfn._xlws.FILTER(BASE_OP!$A$2:$A$9916,(BASE_OP!$I$2:$I$9916="Aguardando Material")*(BASE_OP!$A$2:$A$9916<>"")))),0)} -> 1 | D13: 46237 | E13: {=IFERROR(INDEX(_xlfn._xlws.FILTER(BASE_OP!$D$2:$D$9916,BASE_OP!$G$2:$G$9916=D13),COUNTIF($D$2:D13,D13)),"")} -> 220 | F13: {=IFERROR(INDEX(_xlfn._xlws.FILTER(BASE_OP!$F$2:$F$9916,BASE_OP!$G$2:$G$9916=D13),COUNTIF($D$2:D13,D13)),0)} -> 220 | G13: =IF(E13="","",MAX(0,E13-F13)) -> 0
D14: 46237 | E14: {=IFERROR(INDEX(_xlfn._xlws.FILTER(BASE_OP!$D$2:$D$9916,BASE_OP!$G$2:$G$9916=D14),COUNTIF($D$2:D14,D14)),"")} -> 1 | F14: {=IFERROR(INDEX(_xlfn._xlws.FILTER(BASE_OP!$F$2:$F$9916,BASE_OP!$G$2:$G$9916=D14),COUNTIF($D$2:D14,D14)),0)} -> 1 | G14: =IF(E14="","",MAX(0,E14-F14)) -> 0
D15: 46237 | E15: {=IFERROR(INDEX(_xlfn._xlws.FILTER(BASE_OP!$D$2:$D$9916,BASE_OP!$G$2:$G$9916=D15),COUNTIF($D$2:D15,D15)),"")} -> 1 | F15: {=IFERROR(INDEX(_xlfn._xlws.FILTER(BASE_OP!$F$2:$F$9916,BASE_OP!$G$2:$G$9916=D15),COUNTIF($D$2:D15,D15)),0)} -> 1 | G15: =IF(E15="","",MAX(0,E15-F15)) -> 0
D16: 46237 | E16: {=IFERROR(INDEX(_xlfn._xlws.FILTER(BASE_OP!$D$2:$D$9916,BASE_OP!$G$2:$G$9916=D16),COUNTIF($D$2:D16,D16)),"")} -> 1 | F16: {=IFERROR(INDEX(_xlfn._xlws.FILTER(BASE_OP!$F$2:$F$9916,BASE_OP!$G$2:$G$9916=D16),COUNTIF($D$2:D16,D16)),0)} -> 1 | G16: =IF(E16="","",MAX(0,E16-F16)) -> 0
D17: 46237 | E17: {=IFERROR(INDEX(_xlfn._xlws.FILTER(BASE_OP!$D$2:$D$9916,BASE_OP!$G$2:$G$9916=D17),COUNTIF($D$2:D17,D17)),"")} -> 1 | F17: {=IFERROR(INDEX(_xlfn._xlws.FILTER(BASE_OP!$F$2:$F$9916,BASE_OP!$G$2:$G$9916=D17),COUNTIF($D$2:D17,D17)),0)} -> 1 | G17: =IF(E17="","",MAX(0,E17-F17)) -> 0
D18: 46237 | E18: {=IFERROR(INDEX(_xlfn._xlws.FILTER(BASE_OP!$D$2:$D$9916,BASE_OP!$G$2:$G$9916=D18),COUNTIF($D$2:D18,D18)),"")} -> 1 | F18: {=IFERROR(INDEX(_xlfn._xlws.FILTER(BASE_OP!$F$2:$F$9916,BASE_OP!$G$2:$G$9916=D18),COUNTIF($D$2:D18,D18)),0)} -> 1 | G18: =IF(E18="","",MAX(0,E18-F18)) -> 0
D19: 46237 | E19: {=IFERROR(INDEX(_xlfn._xlws.FILTER(BASE_OP!$D$2:$D$9916,BASE_OP!$G$2:$G$9916=D19),COUNTIF($D$2:D19,D19)),"")} -> 1 | F19: {=IFERROR(INDEX(_xlfn._xlws.FILTER(BASE_OP!$F$2:$F$9916,BASE_OP!$G$2:$G$9916=D19),COUNTIF($D$2:D19,D19)),0)} -> 1 | G19: =IF(E19="","",MAX(0,E19-F19)) -> 0
D20: 46237 | E20: {=IFERROR(INDEX(_xlfn._xlws.FILTER(BASE_OP!$D$2:$D$9916,BASE_OP!$G$2:$G$9916=D20),COUNTIF($D$2:D20,D20)),"")} -> 1 | F20: {=IFERROR(INDEX(_xlfn._xlws.FILTER(BASE_OP!$F$2:$F$9916,BASE_OP!$G$2:$G$9916=D20),COUNTIF($D$2:D20,D20)),0)} -> 1 | G20: =IF(E20="","",MAX(0,E20-F20)) -> 0
D21: 46238 | E21: {=IFERROR(INDEX(_xlfn._xlws.FILTER(BASE_OP!$D$2:$D$9916,BASE_OP!$G$2:$G$9916=D21),COUNTIF($D$2:D21,D21)),"")} -> 1 | F21: {=IFERROR(INDEX(_xlfn._xlws.FILTER(BASE_OP!$F$2:$F$9916,BASE_OP!$G$2:$G$9916=D21),COUNTIF($D$2:D21,D21)),0)} -> 1 | G21: =IF(E21="","",MAX(0,E21-F21)) -> 0
D22: 46238 | E22: {=IFERROR(INDEX(_xlfn._xlws.FILTER(BASE_OP!$D$2:$D$9916,BASE_OP!$G$2:$G$9916=D22),COUNTIF($D$2:D22,D22)),"")} -> 1 | F22: {=IFERROR(INDEX(_xlfn._xlws.FILTER(BASE_OP!$F$2:$F$9916,BASE_OP!$G$2:$G$9916=D22),COUNTIF($D$2:D22,D22)),0)} -> 1 | G22: =IF(E22="","",MAX(0,E22-F22)) -> 0
D23: 46238 | E23: {=IFERROR(INDEX(_xlfn._xlws.FILTER(BASE_OP!$D$2:$D$9916,BASE_OP!$G$2:$G$9916=D23),COUNTIF($D$2:D23,D23)),"")} -> 1 | F23: {=IFERROR(INDEX(_xlfn._xlws.FILTER(BASE_OP!$F$2:$F$9916,BASE_OP!$G$2:$G$9916=D23),COUNTIF($D$2:D23,D23)),0)} -> 1 | G23: =IF(E23="","",MAX(0,E23-F23)) -> 0
D24: 46238 | E24: {=IFERROR(INDEX(_xlfn._xlws.FILTER(BASE_OP!$D$2:$D$9916,BASE_OP!$G$2:$G$9916=D24),COUNTIF($D$2:D24,D24)),"")} -> 1 | F24: {=IFERROR(INDEX(_xlfn._xlws.FILTER(BASE_OP!$F$2:$F$9916,BASE_OP!$G$2:$G$9916=D24),COUNTIF($D$2:D24,D24)),0)} -> 1 | G24: =IF(E24="","",MAX(0,E24-F24)) -> 0
D25: 46238 | E25: {=IFERROR(INDEX(_xlfn._xlws.FILTER(BASE_OP!$D$2:$D$9916,BASE_OP!$G$2:$G$9916=D25),COUNTIF($D$2:D25,D25)),"")} -> 1 | F25: {=IFERROR(INDEX(_xlfn._xlws.FILTER(BASE_OP!$F$2:$F$9916,BASE_OP!$G$2:$G$9916=D25),COUNTIF($D$2:D25,D25)),0)} -> 1 | G25: =IF(E25="","",MAX(0,E25-F25)) -> 0
... D102: 46265 | E102: {=IFERROR(INDEX(_xlfn._xlws.FILTER(BASE_OP!$D$2:$D$9916,BASE_OP!$G$2:$G$9916=D102),COUNTIF($D$2:D102,D102)),"")} -> 1 | F102: {=IFERROR(INDEX(_xlfn._xlws.FILTER(BASE_OP!$F$2:$F$9916,BASE_OP!$G$2:$G$9916=D102),COUNTIF($D$2:D102,D102)),0)} -> 0 | G102: =IF(E102="","",MAX(0,E102-F102)) -> 1

Sheet Planilha4
A1: =SEERRO(
A2: CONT.VALORES(ÚNICO(FILTRO(BASE_OP!$A$2:$A$9916;
A3: (BASE_OP!$H$2:$H$9916<>"")*
A4: (BASE_OP!$H$2:$H$9916<=BASE_OP!$G$2:$G$9916)*
A5: (BASE_OP!$A$2:$A$9916<>"")*
A6: SE(DASHBOARD!$H$3="Todos";1;BASE_OP!$C$2:$C$9916=DASHBOARD!$H$3)
A7: )))
A8: /
A9: CONT.VALORES(ÚNICO(FILTRO(BASE_OP!$A$2:$A$9916;
A10: (BASE_OP!$A$2:$A$9916<>"")*
A11: SE(DASHBOARD!$H$3="Todos";1;BASE_OP!$C$2:$C$9916=DASHBOARD!$H$3)
A12: )));
A13: 0)
